Workbook

Sheet TASKS
A1: file:///D:/C2%20_Project%20_Tesla%20Social%20Media%20Analytics_Tesla%20(Set3).pdf

Sheet Posts
A1: Post ID | B1: Platform | C1: Date | D1: Content Type | E1: Post Text | F1: Likes | G1: Shares | H1: Comments | I1: Impressions | J1: Reach | K1: Clicks | L1: Hashtags Used | M1: Campaign_Name
A2: P001 | B2: Twitter | C2: 2024-12-23 | D2: Reel | E2: Check out our latest reel on twitter! | F2: 1461 | G2: 184 | H2: 344 | I2: 21915 | J2: 21675 | K2: 15 | L2: #FutureOfDriving,#AnytimeIsTeslaTime | M2: CybertruckLaunch
A3: P002 | B3: Twitter | C3: 2025-04-03 | D3: Text | E3: Check out our latest text on twitter! | F3: 4054 | G3: 389 | H3: 493 | I3: 64864 | J3: 64383 | K3: 117 | L3: #TeslaCoInnovation,#BetterWithTesla | M3: ModelYCampaign
A4: P003 | B4: YouTube | C4: 2025-05-12 | D4: Reel | E4: Check out our latest reel on youtube! | F4: 2795 | G4: 105 | H4: 49 | I4: 53105 | J4: 52307 | K4: 204 | L4: #TeslaCoInnovation | M4: FSDUpdate
A5: P004 | B5: Instagram | C5: 2024-08-12 | D5: Story | E5: Check out our latest story on instagram! | F5: 2404 | G5: 363 | H5: 138 | I5: 19232 | J5: 18636 | K5: 128 | L5: #EVRevolution | M5: SustainabilityDrive
A6: P005 | B6: YouTube | C6: 2024-06-26 | D6: Reel | E6: Check out our latest reel on youtube! | F6: 3557 | G6: 687 | H6: 424 | I6: 71140 | J6: 70701 | K6: 224 | L6: #EVRevolution,#TeslaCoInnovation | M6: CybertruckLaunch
A7: P006 | B7: Facebook | C7: 2024-10-31 | D7: Carousel | E7: Check out our latest carousel on facebook! | F7: 2945 | G7: 930 | H7: 355 | I7: 23560 | J7: 23275 | K7: 256 | L7: #TeslaCoInnovation | M7: ModelYCampaign
A8: P007 | B8: Twitter | C8: 2024-06-24 | D8: Carousel | E8: Check out our latest carousel on twitter! | F8: 3860 | G8: 201 | H8: 279 | I8: 61760 | J8: 61660 | K8: 235 | L8: #TeslaCoInnovation | M8: ModelYCampaign
A9: P008 | B9: YouTube | C9: 2024-07-13 | D9: Image | E9: Check out our latest image on youtube! | F9: 3929 | G9: 262 | H9: 278 | I9: 43219 | J9: 42841 | K9: 39 | L9: #EVRevolution | M9: SustainabilityDrive
A10: P009 | B10: Facebook | C10: 2024-08-30 | D10: Text | E10: Check out our latest text on facebook! | F10: 3784 | G10: 808 | H10: 404 | I10: 56760 | J10: 56343 | K10: 131 | L10: #TeslaCoInnovation | M10: ModelYCampaign
A11: P010 | B11: Facebook | C11: 2025-03-11 | D11: Image | E11: Check out our latest image on facebook! | F11: 4241 | G11: 902 | H11: 47 | I11: 72097 | J11: 71598 | K11: 167 | L11: #TeslaCoInnovation | M11: ModelYCampaign
A12: P011 | B12: Instagram | C12: 2025-02-02 | D12: Story | E12: Check out our latest story on instagram! | F12: 1792 | G12: 614 | H12: 497 | I12: 25088 | J12: 24675 | K12: 65 | L12: #FutureOfDriving | M12: SustainabilityDrive
A13: P012 | B13: Facebook | C13: 2024-07-21 | D13: Reel | E13: Check out our latest reel on facebook! | F13: 1946 | G13: 686 | H13: 377 | I13: 23352 | J13: 22982 | K13: 213 | L13: #FutureOfDriving | M13: FSDUpdate
A14: P013 | B14: YouTube | C14: 2024-11-18 | D14: Carousel | E14: Check out our latest carousel on youtube! | F14: 1171 | G14: 286 | H14: 231 | I14: 22249 | J14: 21282 | K14: 114 | L14: #EVRevolution | M14: CybertruckLaunch
A15: P014 | B15: Facebook | C15: 2025-02-16 | D15: Story | E15: Check out our latest story on facebook! | F15: 4242 | G15: 555 | H15: 131 | I15: 33936 | J15: 33802 | K15: 265 | L15: #FutureOfDriving
A16: P015 | B16: Facebook | C16: 2024-10-24 | D16: Video | E16: Check out our latest video on facebook! | F16: 3888 | G16: 604 | H16: 128 | I16: 77760 | J16: 77167 | K16: 20 | L16: #FutureOfDriving | M16: CybertruckLaunch
A17: P016 | B17: Facebook | C17: 2024-08-26 | D17: Text | E17: Check out our latest text on facebook! | F17: 3452 | G17: 377 | H17: 360 | I17: 55232 | J17: 55075 | K17: 87 | L17: #FutureOfDriving | M17: FSDUpdate
A18: P017 | B18: Facebook | C18: 2025-05-05 | D18: Text | E18: Check out our latest text on facebook! | F18: 4441 | G18: 511 | H18: 70 | I18: 53292 | J18: 53082 | K18: 159 | L18: #EVRevolution | M18: SustainabilityDrive
A19: P018 | B19: Instagram | C19: 2024-08-19 | D19: Reel | E19: Check out our latest reel on instagram! | F19: 3000 | G19: 382 | H19: 325 | I19: 36000 | J19: 35819 | K19: 19 | L19: #FutureOfDriving | M19: CybertruckLaunch
A20: P019 | B20: Instagram | C20: 2024-06-23 | D20: Video | E20: Check out our latest video on instagram! | F20: 1071 | G20: 519 | H20: 22 | I20: 16065 | J20: 15865 | K20: 103 | L20: #TeslaCoInnovation | M20: SustainabilityDrive
A21: P020 | B21: Instagram | C21: 2024-09-09 | D21: Carousel | E21: Check out our latest carousel on instagram! | F21: 4054 | G21: 488 | H21: 373 | I21: 77026 | J21: 76881 | K21: 25 | L21: #TeslaCoInnovation | M21: CybertruckLaunch
A22: P021 | B22: Instagram | C22: 2025-01-04 | D22: Reel | E22: Check out our latest reel on instagram! | F22: 4838 | G22: 640 | H22: 128 | I22: 72570 | J22: 72396 | K22: 83 | L22: #FutureOfDriving | M22: SustainabilityDrive
A23: P022 | B23: Facebook | C23: 2025-02-27 | D23: Text | E23: Check out our latest text on facebook! | F23: 1570 | G23: 187 | H23: 260 | I23: 25120 | J23: 24613 | K23: 133 | L23: #TeslaCoInnovation | M23: SustainabilityDrive
A24: P023 | B24: Facebook | C24: 2024-11-06 | D24: Video | E24: Check out our latest video on facebook! | F24: 1606 | G24: 547 | H24: 316 | I24: 32120 | J24: 31736 | K24: 225 | L24: #TeslaCoInnovation,#AnytimeIsTeslaTime | M24: ModelYCampaign
A25: P024 | B25: Facebook | C25: 2025-01-23 | D25: Video | E25: Check out our latest video on facebook! | F25: 3961 | G25: 761 | H25: 131 | I25: 67337 | J25: 66615 | K25: 161 | L25: #FutureOfDriving | M25: FSDUpdate
A26: P025 | B26: Twitter | C26: 2025-04-10 | D26: Carousel | E26: Check out our latest carousel on twitter! | F26: 3128 | G26: 211 | H26: 197 | I26: 59432 | J26: 59182 | K26: 238 | L26: #EVRevolution
A27: P026 | B27: YouTube | C27: 2025-04-05 | D27: Reel | E27: Check out our latest reel on youtube! | F27: 3009 | G27: 413 | H27: 358 | I27: 42126 | J27: 41309 | K27: 211 | L27: #FutureOfDriving | M27: ModelYCampaign
A28: P027 | B28: YouTube | C28: 2024-09-17 | D28: Text | E28: Check out our latest text on youtube! | F28: 2076 | G28: 195 | H28: 104 | I28: 33216 | J28: 32244 | K28: 51 | L28: #FutureOfDriving | M28: SustainabilityDrive
A29: P028 | B29: Instagram | C29: 2025-03-04 | D29: Video | E29: Check out our latest video on instagram! | F29: 432 | G29: 624 | H29: 123 | I29: 6912 | J29: 6259 | K29: 79 | L29: #FutureOfDriving | M29: SustainabilityDrive
A30: P029 | B30: Instagram | C30: 2025-01-31 | D30: Carousel | E30: Check out our latest carousel on instagram! | F30: 2566 | G30: 118 | H30: 37 | I30: 12830 | J30: 12264 | K30: 221 | L30: #FutureOfDriving | M30: FSDUpdate
A31: P030 | B31: Instagram | C31: 2025-02-25 | D31: Video | E31: Check out our latest video on instagram! | F31: 3095 | G31: 39 | H31: 78 | I31: 55710 | J31: 54808 | K31: 93 | L31: #EVRevolution
A32: P031 | B32: Instagram | C32: 2024-12-16 | D32: Text | E32: Check out our latest text on instagram! | F32: 438 | G32: 153 | H32: 275 | I32: 3066 | J32: 2701 | K32: 282 | L32: #TeslaCoInnovation | M32: ModelYCampaign
A33: P032 | B33: Twitter | C33: 2024-07-31 | D33: Carousel | E33: Check out our latest carousel on twitter! | F33: 2278 | G33: 10 | H33: 321 | I33: 13668 | J33: 12676 | K33: 275 | L33: #EVRevolution | M33: CybertruckLaunch
A34: P033 | B34: Facebook | C34: 2024-08-21 | D34: Image | E34: Check out our latest image on facebook! | F34: 1407 | G34: 400 | H34: 351 | I34: 16884 | J34: 15954 | K34: 113 | L34: #TeslaCoInnovation | M34: CybertruckLaunch
A35: P034 | B35: Facebook | C35: 2025-03-26 | D35: Text | E35: Check out our latest text on facebook! | F35: 1652 | G35: 89 | H35: 357 | I35: 29736 | J35: 28771 | K35: 215 | L35: #TeslaCoInnovation | M35: FSDUpdate
A36: P035 | B36: Instagram | C36: 2024-11-30 | D36: Video | E36: Check out our latest video on instagram! | F36: 3775 | G36: 16 | H36: 239 | I36: 33975 | J36: 33310 | K36: 271 | L36: #FutureOfDriving | M36: ModelYCampaign
A37: P036 | B37: Instagram | C37: 2025-04-19 | D37: Story | E37: Check out our latest story on instagram! | F37: 4518 | G37: 285 | H37: 383 | I37: 67770 | J37: 67621 | K37: 31 | L37: #EVRevolution | M37: ModelYCampaign
A38: P037 | B38: Facebook | C38: 2025-01-06 | D38: Carousel | E38: Check out our latest carousel on facebook! | F38: 3024 | G38: 925 | H38: 350 | I38: 24192 | J38: 23518 | K38: 36 | L38: #EVRevolution | M38: ModelYCampaign
A39: P038 | B39: YouTube | C39: 2025-02-17 | D39: Reel | E39: Check out our latest reel on youtube! | F39: 3138 | G39: 123 | H39: 291 | I39: 28242 | J39: 27550 | K39: 87 | L39: #TeslaCoInnovation | M39: SustainabilityDrive
A40: P039 | B40: Facebook | C40: 2024-11-25 | D40: Image | E40: Check out our latest image on facebook! | F40: 3564 | G40: 629 | H40: 177 | I40: 60588 | J40: 59627 | K40: 92 | L40: #TeslaCoInnovation
...

Sheet Engagement Summary
A1: Week_Start_Date | B1: Platform | C1: New_Followers | D1: Unfollows | E1: Total_Followers | F1: Engagement_Rate | G1: Ad_Spend
A2: 2024-06-03 | B2: Instagram | C2: 1135 | D2: 88 | E2: 344084 | F2: 8.06 | G2: 5904
A3: 2024-06-03 | B3: Facebook | C3: 1312 | D3: 310 | E3: 42654 | F3: 4.98 | G3: 9566
A4: 2024-06-03 | B4: Twitter | C4: 584 | D4: 169 | E4: 146834 | F4: 8.31 | G4: 26752
A5: 2024-06-03 | B5: YouTube | C5: 1535 | D5: 445 | E5: 395536 | F5: 4.11 | G5: 30671
A6: 2024-06-10 | B6: Instagram | C6: 656 | D6: 139 | E6: 49157 | F6: 9.05 | G6: 9920
A7: 2024-06-10 | B7: Facebook | C7: 1697 | D7: 414 | E7: 316555 | F7: 2.37 | G7: 7924
A8: 2024-06-10 | B8: Twitter | C8: 436 | D8: 250 | E8: 254347 | F8: 4.01 | G8: 8912
A9: 2024-06-10 | B9: YouTube | C9: 1197 | D9: 203 | E9: 413878 | F9: 3.16 | G9: 21205
A10: 2024-06-17 | B10: Instagram | C10: 1048 | D10: 155 | E10: 456946 | F10: 2.46 | G10: 11329
A11: 2024-06-17 | B11: Facebook | C11: 1753 | D11: 371 | E11: 169496 | F11: 8.11 | G11: 46670
A12: 2024-06-17 | B12: Twitter | C12: 1335 | D12: 40 | E12: 122732 | F12: 8.19 | G12: 22482
A13: 2024-06-17 | B13: YouTube | C13: 403 | D13: 66 | E13: 382851 | F13: 3.49 | G13: 24313
... A201: 2025-05-12 | B201: YouTube | C201: 119 | D201: 456 | E201: 82558 | F201: 6.81 | G201: 12174

Sheet Campaign Metadata
A1: Campaign_Name | B1: Start_Date | C1: End_Date | D1: Objective | E1: Total_Budget | F1: Target_Platforms | G1: Primary_Hashtags
A2: CybertruckLaunch | B2: 2024-06-15 | C2: 2024-07-15 | D2: Product Awareness | E2: 150000 | F2: Instagram,Facebook | G2: #EVRevolution,#TeslaCoInnovation
A3: ModelYCampaign | B3: 2024-10-01 | C3: 2024-10-31 | D3: Customer Engagement | E3: 200000 | F3: Instagram,YouTube | G3: #AnytimeIsTeslaTime,
A4: FSDUpdate | B4: 2024-12-25 | C4: 2025-01-10 | D4: Vehicle Launch | E4: 250000 | F4: Facebook,Twitter | G4: #SmoothLikeNitroTesla
A5: SustainabilityDrive | B5: 2025-03-01 | C5: 2025-03-31 | D5: Community Growth | E5: 180000 | F5: Instagram,Twitter | G5: #BetterWithTesla,#FutureOfDriving

Sheet TASK 1
A1: Post ID | B1: Platform | C1: Date | D1: Content Type | E1: Post Text | F1: Likes | G1: Shares | H1: Comments | I1: Impressions | J1: Reach | K1: Clicks | L1: Hashtags | M1: Campaign_Name | N1: Column1
A2: P001 | B2: Twitter | C2: 45649 | D2: Reel | E2: Check out our latest reel on twitter! | F2: 1461 | G2: 184 | H2: 344 | I2: 21915 | J2: 21675 | K2: 15 | L2: #FutureOfDriving | M2: CybertruckLaunch
A3: P001 | B3: Twitter | C3: 45649 | D3: Reel | E3: Check out our latest reel on twitter! | F3: 1461 | G3: 184 | H3: 344 | I3: 21915 | J3: 21675 | K3: 15 | L3: #AnytimeIsTeslaTime | M3: CybertruckLaunch
A4: P002 | B4: Twitter | C4: 45750 | D4: Text | E4: Check out our latest text on twitter! | F4: 4054 | G4: 389 | H4: 493 | I4: 64864 | J4: 64383 | K4: 117 | L4: #TeslaCoInnovation | M4: ModelYCampaign
A5: P002 | B5: Twitter | C5: 45750 | D5: Text | E5: Check out our latest text on twitter! | F5: 4054 | G5: 389 | H5: 493 | I5: 64864 | J5: 64383 | K5: 117 | L5: #BetterWithTesla | M5: ModelYCampaign
A6: P003 | B6: YouTube | C6: 45789 | D6: Reel | E6: Check out our latest reel on youtube! | F6: 2795 | G6: 105 | H6: 49 | I6: 53105 | J6: 52307 | K6: 204 | L6: #TeslaCoInnovation | M6: FSDUpdate
A7: P004 | B7: Instagram | C7: 45516 | D7: Story | E7: Check out our latest story on instagram! | F7: 2404 | G7: 363 | H7: 138 | I7: 19232 | J7: 18636 | K7: 128 | L7: #EVRevolution | M7: SustainabilityDrive
A8: P005 | B8: YouTube | C8: 45469 | D8: Reel | E8: Check out our latest reel on youtube! | F8: 3557 | G8: 687 | H8: 424 | I8: 71140 | J8: 70701 | K8: 224 | L8: #EVRevolution | M8: CybertruckLaunch
A9: P005 | B9: YouTube | C9: 45469 | D9: Reel | E9: Check out our latest reel on youtube! | F9: 3557 | G9: 687 | H9: 424 | I9: 71140 | J9: 70701 | K9: 224 | L9: #TeslaCoInnovation | M9: CybertruckLaunch
A10: P006 | B10: Facebook | C10: 45596 | D10: Carousel | E10: Check out our latest carousel on facebook! | F10: 2945 | G10: 930 | H10: 355 | I10: 23560 | J10: 23275 | K10: 256 | L10: #TeslaCoInnovation | M10: ModelYCampaign
A11: P007 | B11: Twitter | C11: 45467 | D11: Carousel | E11: Check out our latest carousel on twitter! | F11: 3860 | G11: 201 | H11: 279 | I11: 61760 | J11: 61660 | K11: 235 | L11: #TeslaCoInnovation | M11: ModelYCampaign
A12: P008 | B12: YouTube | C12: 45486 | D12: Image | E12: Check out our latest image on youtube! | F12: 3929 | G12: 262 | H12: 278 | I12: 43219 | J12: 42841 | K12: 39 | L12: #EVRevolution | M12: SustainabilityDrive
A13: P009 | B13: Facebook | C13: 45534 | D13: Text | E13: Check out our latest text on facebook! | F13: 3784 | G13: 808 | H13: 404 | I13: 56760 | J13: 56343 | K13: 131 | L13: #TeslaCoInnovation | M13: ModelYCampaign
... A17: P013 | B17: YouTube | C17: 45614 | D17: Carousel | E17: Check out our latest carousel on youtube! | F17: 1171 | G17: 286 | H17: 231 | I17: 22249 | J17: 21282 | K17: 114 | L17: #EVRevolution | M17: CybertruckLaunch
A18: P014 | B18: Facebook | C18: 45704 | D18: Story | E18: Check out our latest story on facebook! | F18: 4242 | G18: 555 | H18: 131 | I18: 33936 | J18: 33802 | K18: 265 | L18: #FutureOfDriving
A19: P015 | B19: Facebook | C19: 45589 | D19: Video | E19: Check out our latest video on facebook! | F19: 3888 | G19: 604 | H19: 128 | I19: 77760 | J19: 77167 | K19: 20 | L19: #FutureOfDriving | M19: CybertruckLaunch
A20: P016 | B20: Facebook | C20: 45530 | D20: Text | E20: Check out our latest text on facebook! | F20: 3452 | G20: 377 | H20: 360 | I20: 55232 | J20: 55075 | K20: 87 | L20: #FutureOfDriving | M20: FSDUpdate
A21: P017 | B21: Facebook | C21: 45782 | D21: Text | E21: Check out our latest text on facebook! | F21: 4441 | G21: 511 | H21: 70 | I21: 53292 | J21: 53082 | K21: 159 | L21: #EVRevolution | M21: SustainabilityDrive
A22: P018 | B22: Instagram | C22: 45523 | D22: Reel | E22: Check out our latest reel on instagram! | F22: 3000 | G22: 382 | H22: 325 | I22: 36000 | J22: 35819 | K22: 19 | L22: #FutureOfDriving | M22: CybertruckLaunch
A23: P019 | B23: Instagram | C23: 45466 | D23: Video | E23: Check out our latest video on instagram! | F23: 1071 | G23: 519 | H23: 22 | I23: 16065 | J23: 15865 | K23: 103 | L23: #TeslaCoInnovation | M23: SustainabilityDrive
A24: P020 | B24: Instagram | C24: 45544 | D24: Carousel | E24: Check out our latest carousel on instagram! | F24: 4054 | G24: 488 | H24: 373 | I24: 77026 | J24: 76881 | K24: 25 | L24: #TeslaCoInnovation | M24: CybertruckLaunch
A25: P021 | B25: Instagram | C25: 45661 | D25: Reel | E25: Check out our latest reel on instagram! | F25: 4838 | G25: 640 | H25: 128 | I25: 72570 | J25: 72396 | K25: 83 | L25: #FutureOfDriving | M25: SustainabilityDrive
A26: P022 | B26: Facebook | C26: 45715 | D26: Text | E26: Check out our latest text on facebook! | F26: 1570 | G26: 187 | H26: 260 | I26: 25120 | J26: 24613 | K26: 133 | L26: #TeslaCoInnovation | M26: SustainabilityDrive
A27: P023 | B27: Facebook | C27: 45602 | D27: Video | E27: Check out our latest video on facebook! | F27: 1606 | G27: 547 | H27: 316 | I27: 32120 | J27: 31736 | K27: 225 | L27: #TeslaCoInnovation | M27: ModelYCampaign
A28: P023 | B28: Facebook | C28: 45602 | D28: Video | E28: Check out our latest video on facebook! | F28: 1606 | G28: 547 | H28: 316 | I28: 32120 | J28: 31736 | K28: 225 | L28: #AnytimeIsTeslaTime | M28: ModelYCampaign
A29: P024 | B29: Facebook | C29: 45680 | D29: Video | E29: Check out our latest video on facebook! | F29: 3961 | G29: 761 | H29: 131 | I29: 67337 | J29: 66615 | K29: 161 | L29: #FutureOfDriving | M29: FSDUpdate
A30: P025 | B30: Twitter | C30: 45757 | D30: Carousel | E30: Check out our latest carousel on twitter! | F30: 3128 | G30: 211 | H30: 197 | I30: 59432 | J30: 59182 | K30: 238 | L30: #EVRevolution
A31: P026 | B31: YouTube | C31: 45752 | D31: Reel | E31: Check out our latest reel on youtube! | F31: 3009 | G31: 413 | H31: 358 | I31: 42126 | J31: 41309 | K31: 211 | L31: #FutureOfDriving | M31: ModelYCampaign
A32: P027 | B32: YouTube | C32: 45552 | D32: Text | E32: Check out our latest text on youtube! | F32: 2076 | G32: 195 | H32: 104 | I32: 33216 | J32: 32244 | K32: 51 | L32: #FutureOfDriving | M32: SustainabilityDrive
A33: P028 | B33: Instagram | C33: 45720 | D33: Video | E33: Check out our latest video on instagram! | F33: 432 | G33: 624 | H33: 123 | I33: 6912 | J33: 6259 | K33: 79 | L33: #FutureOfDriving | M33: SustainabilityDrive
A34: P029 | B34: Instagram | C34: 45688 | D34: Carousel | E34: Check out our latest carousel on instagram! | F34: 2566 | G34: 118 | H34: 37 | I34: 12830 | J34: 12264 | K34: 221 | L34: #FutureOfDriving | M34: FSDUpdate
A35: P030 | B35: Instagram | C35: 45713 | D35: Video | E35: Check out our latest video on instagram! | F35: 3095 | G35: 39 | H35: 78 | I35: 55710 | J35: 54808 | K35: 93 | L35: #EVRevolution
A36: P031 | B36: Instagram | C36: 45642 | D36: Text | E36: Check out our latest text on instagram! | F36: 438 | G36: 153 | H36: 275 | I36: 3066 | J36: 2701 | K36: 282 | L36: #TeslaCoInnovation | M36: ModelYCampaign
A37: P032 | B37: Twitter | C37: 45504 | D37: Carousel | E37: Check out our latest carousel on twitter! | F37: 2278 | G37: 10 | H37: 321 | I37: 13668 | J37: 12676 | K37: 275 | L37: #EVRevolution | M37: CybertruckLaunch
A38: P033 | B38: Facebook | C38: 45525 | D38: Image | E38: Check out our latest image on facebook! | F38: 1407 | G38: 400 | H38: 351 | I38: 16884 | J38: 15954 | K38: 113 | L38: #TeslaCoInnovation | M38: CybertruckLaunch
A39: P034 | B39: Facebook | C39: 45742 | D39: Text | E39: Check out our latest text on facebook! | F39: 1652 | G39: 89 | H39: 357 | I39: 29736 | J39: 28771 | K39: 215 | L39: #TeslaCoInnovation | M39: FSDUpdate
A40: P035 | B40: Instagram | C40: 45626 | D40: Video | E40: Check out our latest video on instagram! | F40: 3775 | G40: 16 | H40: 239 | I40: 33975 | J40: 33310 | K40: 271 | L40: #FutureOfDriving | M40: ModelYCampaign
A41: P036 | B41: Instagram | C41: 45766 | D41: Story | E41: Check out our latest story on instagram! | F41: 4518 | G41: 285 | H41: 383 | I41: 67770 | J41: 67621 | K41: 31 | L41: #EVRevolution | M41: ModelYCampaign
A42: P037 | B42: Facebook | C42: 45663 | D42: Carousel | E42: Check out our latest carousel on facebook! | F42: 3024 | G42: 925 | H42: 350 | I42: 24192 | J42: 23518 | K42: 36 | L42: #EVRevolution | M42: ModelYCampaign
A43: P038 | B43: YouTube | C43: 45705 | D43: Reel | E43: Check out our latest reel on youtube! | F43: 3138 | G43: 123 | H43: 291 | I43: 28242 | J43: 27550 | K43: 87 | L43: #TeslaCoInnovation | M43: SustainabilityDrive
...

Sheet TASK 2(3)
B5: Column Labels
B6: Facebook | E6: Instagram | H6: Twitter | K6: YouTube | N6: Total Sum of Likes | O6: Total Sum of Shares | P6: Total Sum of Comments
A7: Row Labels | B7: Sum of Likes | C7: Sum of Shares | D7: Sum of Comments | E7: Sum of Likes | F7: Sum of Shares | G7: Sum of Comments | H7: Sum of Likes | I7: Sum of Shares | J7: Sum of Comments | K7: Sum of Likes | L7: Sum of Shares | M7: Sum of Comments
A8: Carousel | B8: 44476 | C8: 7400 | D8: 4589 | E8: 45776 | F8: 7903 | G8: 4382 | H8: 63769 | I8: 7949 | J8: 4622 | K8: 25730 | L8: 6944 | M8: 2465 | N8: 179751 | O8: 30196 | P8: 16058
A9: Image | B9: 76983 | C9: 13679 | D9: 7144 | E9: 40391 | F9: 5989 | G9: 3646 | H9: 50158 | I9: 7895 | J9: 5743 | K9: 23903 | L9: 4310 | M9: 2077 | N9: 191435 | O9: 31873 | P9: 18610
A10: Reel | B10: 46102 | C10: 7149 | D10: 3732 | E10: 32148 | F10: 8110 | G10: 3386 | H10: 28490 | I10: 4734 | J10: 2257 | K10: 39022 | L10: 6036 | M10: 3234 | N10: 145762 | O10: 26029 | P10: 12609
A11: Story | B11: 29405 | C11: 4950 | D11: 3223 | E11: 51313 | F11: 11591 | G11: 4284 | H11: 20466 | I11: 5090 | J11: 3026 | K11: 31968 | L11: 3866 | M11: 2012 | N11: 133152 | O11: 25497 | P11: 12545
A12: Text | B12: 35357 | C12: 5127 | D12: 4424 | E12: 25567 | F12: 5112 | G12: 1946 | H12: 35953 | I12: 5250 | J12: 4403 | K12: 35429 | L12: 5204 | M12: 1293 | N12: 132306 | O12: 20693 | P12: 12066
A13: Video | B13: 30553 | C13: 3718 | D13: 2579 | E13: 27578 | F13: 7858 | G13: 2254 | H13: 40013 | I13: 7240 | J13: 3884 | K13: 39835 | L13: 6946 | M13: 3359 | N13: 137979 | O13: 25762 | P13: 12076
A14: Grand Total | B14: 262876 | C14: 42023 | D14: 25691 | E14: 222773 | F14: 46563 | G14: 19898 | H14: 238849 | I14: 38158 | J14: 23935 | K14: 195887 | L14: 33306 | M14: 14440 | N14: 920385 | O14: 160050 | P14: 83964

Sheet TASK 2(1)
A1: Post ID | B1: Platform | C1: Date | D1: Content Type | E1: Post Text | F1: Likes | G1: Shares | H1: Comments | I1: Impressions | J1: Reach | K1: Clicks | L1: Hashtags Used | M1: Campaign_Name | N1: Engagement Rate
A2: P001 | B2: Twitter | C2: 2024-12-23 | D2: Reel | E2: Check out our latest reel on twitter! | F2: 1461 | G2: 184 | H2: 344 | I2: 21915 | J2: 21675 | K2: 15 | L2: #FutureOfDriving,#AnytimeIsTeslaTime | M2: CybertruckLaunch | N2: =(F2+G2+H2)/I2 -> 0.090759754
A3: P002 | B3: Twitter | C3: 2025-04-03 | D3: Text | E3: Check out our latest text on twitter! | F3: 4054 | G3: 389 | H3: 493 | I3: 64864 | J3: 64383 | K3: 117 | L3: #TeslaCoInnovation,#BetterWithTesla | M3: ModelYCampaign | N3: =(F3+G3+H3)/I3 -> 0.076097681
A4: P003 | B4: YouTube | C4: 2025-05-12 | D4: Reel | E4: Check out our latest reel on youtube! | F4: 2795 | G4: 105 | H4: 49 | I4: 53105 | J4: 52307 | K4: 204 | L4: #TeslaCoInnovation | M4: FSDUpdate | N4: =(F4+G4+H4)/I4 -> 0.055531494
A5: P004 | B5: Instagram | C5: 2024-08-12 | D5: Story | E5: Check out our latest story on instagram! | F5: 2404 | G5: 363 | H5: 138 | I5: 19232 | J5: 18636 | K5: 128 | L5: #EVRevolution | M5: SustainabilityDrive | N5: =(F5+G5+H5)/I5 -> 0.15105033
A6: P005 | B6: YouTube | C6: 2024-06-26 | D6: Reel | E6: Check out our latest reel on youtube! | F6: 3557 | G6: 687 | H6: 424 | I6: 71140 | J6: 70701 | K6: 224 | L6: #EVRevolution,#TeslaCoInnovation | M6: CybertruckLaunch | N6: =(F6+G6+H6)/I6 -> 0.065617093
A7: P006 | B7: Facebook | C7: 2024-10-31 | D7: Carousel | E7: Check out our latest carousel on facebook! | F7: 2945 | G7: 930 | H7: 355 | I7: 23560 | J7: 23275 | K7: 256 | L7: #TeslaCoInnovation | M7: ModelYCampaign | N7: =(F7+G7+H7)/I7 -> 0.1795416
A8: P007 | B8: Twitter | C8: 2024-06-24 | D8: Carousel | E8: Check out our latest carousel on twitter! | F8: 3860 | G8: 201 | H8: 279 | I8: 61760 | J8: 61660 | K8: 235 | L8: #TeslaCoInnovation | M8: ModelYCampaign | N8: =(F8+G8+H8)/I8 -> 0.070272021
A9: P008 | B9: YouTube | C9: 2024-07-13 | D9: Image | E9: Check out our latest image on youtube! | F9: 3929 | G9: 262 | H9: 278 | I9: 43219 | J9: 42841 | K9: 39 | L9: #EVRevolution | M9: SustainabilityDrive | N9: =(F9+G9+H9)/I9 -> 0.1034036
A10: P009 | B10: Facebook | C10: 2024-08-30 | D10: Text | E10: Check out our latest text on facebook! | F10: 3784 | G10: 808 | H10: 404 | I10: 56760 | J10: 56343 | K10: 131 | L10: #TeslaCoInnovation | M10: ModelYCampaign | N10: =(F10+G10+H10)/I10 -> 0.088019732
A11: P010 | B11: Facebook | C11: 2025-03-11 | D11: Image | E11: Check out our latest image on facebook! | F11: 4241 | G11: 902 | H11: 47 | I11: 72097 | J11: 71598 | K11: 167 | L11: #TeslaCoInnovation | M11: ModelYCampaign | N11: =(F11+G11+H11)/I11 -> 0.071986352
A12: P011 | B12: Instagram | C12: 2025-02-02 | D12: Story | E12: Check out our latest story on instagram! | F12: 1792 | G12: 614 | H12: 497 | I12: 25088 | J12: 24675 | K12: 65 | L12: #FutureOfDriving | M12: SustainabilityDrive | N12: =(F12+G12+H12)/I12 -> 0.11571269
A13: P012 | B13: Facebook | C13: 2024-07-21 | D13: Reel | E13: Check out our latest reel on facebook! | F13: 1946 | G13: 686 | H13: 377 | I13: 23352 | J13: 22982 | K13: 213 | L13: #FutureOfDriving | M13: FSDUpdate | N13: =(F13+G13+H13)/I13 -> 0.12885406
A14: P013 | B14: YouTube | C14: 2024-11-18 | D14: Carousel | E14: Check out our latest carousel on youtube! | F14: 1171 | G14: 286 | H14: 231 | I14: 22249 | J14: 21282 | K14: 114 | L14: #EVRevolution | M14: CybertruckLaunch | N14: =(F14+G14+H14)/I14 -> 0.075868578
A15: P014 | B15: Facebook | C15: 2025-02-16 | D15: Story | E15: Check out our latest story on facebook! | F15: 4242 | G15: 555 | H15: 131 | I15: 33936 | J15: 33802 | K15: 265 | L15: #FutureOfDriving | N15: =(F15+G15+H15)/I15 -> 0.14521452
A16: P015 | B16: Facebook | C16: 2024-10-24 | D16: Video | E16: Check out our latest video on facebook! | F16: 3888 | G16: 604 | H16: 128 | I16: 77760 | J16: 77167 | K16: 20 | L16: #FutureOfDriving | M16: CybertruckLaunch | N16: =(F16+G16+H16)/I16 -> 0.05941358
A17: P016 | B17: Facebook | C17: 2024-08-26 | D17: Text | E17: Check out our latest text on facebook! | F17: 3452 | G17: 377 | H17: 360 | I17: 55232 | J17: 55075 | K17: 87 | L17: #FutureOfDriving | M17: FSDUpdate | N17: =(F17+G17+H17)/I17 -> 0.075843714
A18: P017 | B18: Facebook | C18: 2025-05-05 | D18: Text | E18: Check out our latest text on facebook! | F18: 4441 | G18: 511 | H18: 70 | I18: 53292 | J18: 53082 | K18: 159 | L18: #EVRevolution | M18: SustainabilityDrive | N18: =(F18+G18+H18)/I18 -> 0.094235533
A19: P018 | B19: Instagram | C19: 2024-08-19 | D19: Reel | E19: Check out our latest reel on instagram! | F19: 3000 | G19: 382 | H19: 325 | I19: 36000 | J19: 35819 | K19: 19 | L19: #FutureOfDriving | M19: CybertruckLaunch | N19: =(F19+G19+H19)/I19 -> 0.10297222
A20: P019 | B20: Instagram | C20: 2024-06-23 | D20: Video | E20: Check out our latest video on instagram! | F20: 1071 | G20: 519 | H20: 22 | I20: 16065 | J20: 15865 | K20: 103 | L20: #TeslaCoInnovation | M20: SustainabilityDrive | N20: =(F20+G20+H20)/I20 -> 0.10034236
A21: P020 | B21: Instagram | C21: 2024-09-09 | D21: Carousel | E21: Check out our latest carousel on instagram! | F21: 4054 | G21: 488 | H21: 373 | I21: 77026 | J21: 76881 | K21: 25 | L21: #TeslaCoInnovation | M21: CybertruckLaunch | N21: =(F21+G21+H21)/I21 -> 0.063809623
A22: P021 | B22: Instagram | C22: 2025-01-04 | D22: Reel | E22: Check out our latest reel on instagram! | F22: 4838 | G22: 640 | H22: 128 | I22: 72570 | J22: 72396 | K22: 83 | L22: #FutureOfDriving | M22: SustainabilityDrive | N22: =(F22+G22+H22)/I22 -> 0.077249552
A23: P022 | B23: Facebook | C23: 2025-02-27 | D23: Text | E23: Check out our latest text on facebook! | F23: 1570 | G23: 187 | H23: 260 | I23: 25120 | J23: 24613 | K23: 133 | L23: #TeslaCoInnovation | M23: SustainabilityDrive | N23: =(F23+G23+H23)/I23 -> 0.080294586
A24: P023 | B24: Facebook | C24: 2024-11-06 | D24: Video | E24: Check out our latest video on facebook! | F24: 1606 | G24: 547 | H24: 316 | I24: 32120 | J24: 31736 | K24: 225 | L24: #TeslaCoInnovation,#AnytimeIsTeslaTime | M24: ModelYCampaign | N24: =(F24+G24+H24)/I24 -> 0.076867995
A25: P024 | B25: Facebook | C25: 2025-01-23 | D25: Video | E25: Check out our latest video on facebook! | F25: 3961 | G25: 761 | H25: 131 | I25: 67337 | J25: 66615 | K25: 161 | L25: #FutureOfDriving | M25: FSDUpdate | N25: =(F25+G25+H25)/I25 -> 0.072070333
A26: P025 | B26: Twitter | C26: 2025-04-10 | D26: Carousel | E26: Check out our latest carousel on twitter! | F26: 3128 | G26: 211 | H26: 197 | I26: 59432 | J26: 59182 | K26: 238 | L26: #EVRevolution | N26: =(F26+G26+H26)/I26 -> 0.059496568
A27: P026 | B27: YouTube | C27: 2025-04-05 | D27: Reel | E27: Check out our latest reel on youtube! | F27: 3009 | G27: 413 | H27: 358 | I27: 42126 | J27: 41309 | K27: 211 | L27: #FutureOfDriving | M27: ModelYCampaign | N27: =(F27+G27+H27)/I27 -> 0.089730808
A28: P027 | B28: YouTube | C28: 2024-09-17 | D28: Text | E28: Check out our latest text on youtube! | F28: 2076 | G28: 195 | H28: 104 | I28: 33216 | J28: 32244 | K28: 51 | L28: #FutureOfDriving | M28: SustainabilityDrive | N28: =(F28+G28+H28)/I28 -> 0.071501686
A29: P028 | B29: Instagram | C29: 2025-03-04 | D29: Video | E29: Check out our latest video on instagram! | F29: 432 | G29: 624 | H29: 123 | I29: 6912 | J29: 6259 | K29: 79 | L29: #FutureOfDriving | M29: SustainabilityDrive | N29: =(F29+G29+H29)/I29 -> 0.17057292
A30: P029 | B30: Instagram | C30: 2025-01-31 | D30: Carousel | E30: Check out our latest carousel on instagram! | F30: 2566 | G30: 118 | H30: 37 | I30: 12830 | J30: 12264 | K30: 221 | L30: #FutureOfDriving | M30: FSDUpdate | N30: =(F30+G30+H30)/I30 -> 0.21208106
A31: P030 | B31: Instagram | C31: 2025-02-25 | D31: Video | E31: Check out our latest video on instagram! | F31: 3095 | G31: 39 | H31: 78 | I31: 55710 | J31: 54808 | K31: 93 | L31: #EVRevolution | N31: =(F31+G31+H31)/I31 -> 0.057655717
A32: P031 | B32: Instagram | C32: 2024-12-16 | D32: Text | E32: Check out our latest text on instagram! | F32: 438 | G32: 153 | H32: 275 | I32: 3066 | J32: 2701 | K32: 282 | L32: #TeslaCoInnovation | M32: ModelYCampaign | N32: =(F32+G32+H32)/I32 -> 0.28245271
A33: P032 | B33: Twitter | C33: 2024-07-31 | D33: Carousel | E33: Check out our latest carousel on twitter! | F33: 2278 | G33: 10 | H33: 321 | I33: 13668 | J33: 12676 | K33: 275 | L33: #EVRevolution | M33: CybertruckLaunch | N33: =(F33+G33+H33)/I33 -> 0.19088382
A34: P033 | B34: Facebook | C34: 2024-08-21 | D34: Image | E34: Check out our latest image on facebook! | F34: 1407 | G34: 400 | H34: 351 | I34: 16884 | J34: 15954 | K34: 113 | L34: #TeslaCoInnovation | M34: CybertruckLaunch | N34: =(F34+G34+H34)/I34 -> 0.12781331
A35: P034 | B35: Facebook | C35: 2025-03-26 | D35: Text | E35: Check out our latest text on facebook! | F35: 1652 | G35: 89 | H35: 357 | I35: 29736 | J35: 28771 | K35: 215 | L35: #TeslaCoInnovation | M35: FSDUpdate | N35: =(F35+G35+H35)/I35 -> 0.07055421
A36: P035 | B36: Instagram | C36: 2024-11-30 | D36: Video | E36: Check out our latest video on instagram! | F36: 3775 | G36: 16 | H36: 239 | I36: 33975 | J36: 33310 | K36: 271 | L36: #FutureOfDriving | M36: ModelYCampaign | N36: =(F36+G36+H36)/I36 -> 0.11861663
A37: P036 | B37: Instagram | C37: 2025-04-19 | D37: Story | E37: Check out our latest story on instagram! | F37: 4518 | G37: 285 | H37: 383 | I37: 67770 | J37: 67621 | K37: 31 | L37: #EVRevolution | M37: ModelYCampaign | N37: =(F37+G37+H37)/I37 -> 0.076523535
A38: P037 | B38: Facebook | C38: 2025-01-06 | D38: Carousel | E38: Check out our latest carousel on facebook! | F38: 3024 | G38: 925 | H38: 350 | I38: 24192 | J38: 23518 | K38: 36 | L38: #EVRevolution | M38: ModelYCampaign | N38: =(F38+G38+H38)/I38 -> 0.17770337
A39: P038 | B39: YouTube | C39: 2025-02-17 | D39: Reel | E39: Check out our latest reel on youtube! | F39: 3138 | G39: 123 | H39: 291 | I39: 28242 | J39: 27550 | K39: 87 | L39: #TeslaCoInnovation | M39: SustainabilityDrive | N39: =(F39+G39+H39)/I39 -> 0.12577013
A40: P039 | B40: Facebook | C40: 2024-11-25 | D40: Image | E40: Check out our latest image on facebook! | F40: 3564 | G40: 629 | H40: 177 | I40: 60588 | J40: 59627 | K40: 92 | L40: #TeslaCoInnovation | N40: =(F40+G40+H40)/I40 -> 0.072126494
...

Sheet TASK 2(2)
A1: Post ID | B1: Platform | C1: Date | D1: Content Type | E1: Post Text | F1: Likes | G1: Shares | H1: Comments | I1: Impressions | J1: Reach | K1: Clicks | L1: Hashtags Used | M1: Campaign_Name | N1: Engagement Rate
A2: P063 | B2: Twitter | C2: 45504 | D2: Carousel | E2: Check out our latest carousel on twitter! | F2: 4507 | G2: 217 | H2: 13 | I2: 90140 | J2: 89591 | K2: 125 | L2: #FutureOfDriving | M2: FSDUpdate | N2: 0.052551586
A3: P176 | B3: Facebook | C3: 45463 | D3: Video | E3: Check out our latest video on facebook! | F3: 3798 | G3: 31 | H3: 279 | I3: 75960 | J3: 75813 | K3: 266 | L3: #TeslaCoInnovation | M3: CybertruckLaunch | N3: 0.054081095
A4: P003 | B4: YouTube | C4: 45789 | D4: Reel | E4: Check out our latest reel on youtube! | F4: 2795 | G4: 105 | H4: 49 | I4: 53105 | J4: 52307 | K4: 204 | L4: #TeslaCoInnovation | M4: FSDUpdate | N4: 0.055531494
A5: P190 | B5: YouTube | C5: 45569 | D5: Text | E5: Check out our latest text on youtube! | F5: 1963 | G5: 213 | H5: 19 | I5: 39260 | J5: 38771 | K5: 145 | L5: #FutureOfDriving | N5: 0.055909322
A6: P145 | B6: Instagram | C6: 45516 | D6: Carousel | E6: Check out our latest carousel on instagram! | F6: 1878 | G6: 62 | H6: 179 | I6: 37560 | J6: 36874 | K6: 142 | L6: #TeslaCoInnovation | M6: SustainabilityDrive | N6: 0.0564164
A7: P225 | B7: Twitter | C7: 45463 | D7: Carousel | E7: Check out our latest carousel on twitter! | F7: 4672 | G7: 325 | H7: 32 | I7: 88768 | J7: 87833 | K7: 118 | L7: #EVRevolution | N7: 0.056653298
A8: P203 | B8: Instagram | C8: 45617 | D8: Carousel | E8: Check out our latest carousel on instagram! | F8: 3773 | G8: 299 | H8: 38 | I8: 71687 | J8: 71447 | K8: 286 | L8: #FutureOfDriving | M8: CybertruckLaunch | N8: 0.057332571
A9: P030 | B9: Instagram | C9: 45713 | D9: Video | E9: Check out our latest video on instagram! | F9: 3095 | G9: 39 | H9: 78 | I9: 55710 | J9: 54808 | K9: 93 | L9: #EVRevolution | N9: 0.057655717
A10: P256 | B10: YouTube | C10: 45553 | D10: Carousel | E10: Check out our latest carousel on youtube! | F10: 2143 | G10: 12 | H10: 204 | I10: 40717 | J10: 40125 | K10: 248 | L10: #EVRevolution | M10: ModelYCampaign | N10: 0.057936488
A11: P283 | B11: Twitter | C11: 45786 | D11: Reel | E11: Check out our latest reel on twitter! | F11: 3367 | G11: 302 | H11: 57 | I11: 63973 | J11: 63789 | K11: 157 | L11: #FutureOfDriving | M11: ModelYCampaign | N11: 0.058243321
A12: P216 | B12: YouTube | C12: 45502 | D12: Story | E12: Check out our latest story on youtube! | F12: 1509 | G12: 88 | H12: 163 | I12: 30180 | J12: 29689 | K12: 119 | L12: #EVRevolution | M12: ModelYCampaign | N12: 0.058316766
A13: P298 | B13: Facebook | C13: 45589 | D13: Image | E13: Check out our latest image on facebook! | F13: 4303 | G13: 451 | H13: 286 | I13: 86060 | J13: 85823 | K13: 14 | L13: #TeslaCoInnovation | M13: FSDUpdate | N13: 0.058563793
A14: P296 | B14: Twitter | C14: 45699 | D14: Video | E14: Check out our latest video on twitter! | F14: 3440 | G14: 13 | H14: 20 | I14: 58480 | J14: 58146 | K14: 210 | L14: #TeslaCoInnovation | M14: SustainabilityDrive | N14: 0.059387825
A15: P296 | B15: Twitter | C15: 45699 | D15: Video | E15: Check out our latest video on twitter! | F15: 3440 | G15: 13 | H15: 20 | I15: 58480 | J15: 58146 | K15: 210 | L15: #SmoothLikeNitroTesla | M15: SustainabilityDrive | N15: 0.059387825
A16: P015 | B16: Facebook | C16: 45589 | D16: Video | E16: Check out our latest video on facebook! | F16: 3888 | G16: 604 | H16: 128 | I16: 77760 | J16: 77167 | K16: 20 | L16: #FutureOfDriving | M16: CybertruckLaunch | N16: 0.05941358
A17: P025 | B17: Twitter | C17: 45757 | D17: Carousel | E17: Check out our latest carousel on twitter! | F17: 3128 | G17: 211 | H17: 197 | I17: 59432 | J17: 59182 | K17: 238 | L17: #EVRevolution | N17: 0.059496568
A18: P279 | B18: YouTube | C18: 45537 | D18: Image | E18: Check out our latest image on youtube! | F18: 4905 | G18: 845 | H18: 129 | I18: 98100 | J18: 97772 | K18: 279 | L18: #TeslaCoInnovation | M18: ModelYCampaign | N18: 0.059928644
A19: P223 | B19: Twitter | C19: 45608 | D19: Image | E19: Check out our latest image on twitter! | F19: 3338 | G19: 277 | H19: 118 | I19: 60084 | J19: 59842 | K19: 252 | L19: #TeslaCoInnovation | N19: 0.062129685
A20: P115 | B20: Twitter | C20: 45788 | D20: Image | E20: Check out our latest image on twitter! | F20: 2493 | G20: 97 | H20: 44 | I20: 42381 | J20: 41991 | K20: 242 | L20: #TeslaCoInnovation | M20: SustainabilityDrive | N20: 0.062150492
A21: P115 | B21: Twitter | C21: 45788 | D21: Image | E21: Check out our latest image on twitter! | F21: 2493 | G21: 97 | H21: 44 | I21: 42381 | J21: 41991 | K21: 242 | L21: #AnytimeIsTeslaTime | M21: SustainabilityDrive | N21: 0.062150492
A22: P107 | B22: YouTube | C22: 45464 | D22: Image | E22: Check out our latest image on youtube! | F22: 4832 | G22: 893 | H22: 10 | I22: 91808 | J22: 91296 | K22: 182 | L22: #TeslaCoInnovation | N22: 0.062467323
A23: P200 | B23: Facebook | C23: 45754 | D23: Reel | E23: Check out our latest reel on facebook! | F23: 3718 | G23: 385 | H23: 310 | I23: 70642 | J23: 69749 | K23: 233 | L23: #TeslaCoInnovation | M23: ModelYCampaign | N23: 0.062469919
A24: P217 | B24: Facebook | C24: 45629 | D24: Image | E24: Check out our latest image on facebook! | F24: 4606 | G24: 931 | H24: 230 | I24: 92120 | J24: 91440 | K24: 56 | L24: #TeslaCoInnovation | N24: 0.062603126
A25: P281 | B25: YouTube | C25: 45738 | D25: Image | E25: Check out our latest image on youtube! | F25: 3166 | G25: 90 | H25: 341 | I25: 56988 | J25: 56125 | K25: 135 | L25: #EVRevolution | M25: ModelYCampaign | N25: 0.063118551
A26: P150 | B26: YouTube | C26: 45526 | D26: Carousel | E26: Check out our latest carousel on youtube! | F26: 4295 | G26: 853 | H26: 325 | I26: 85900 | J26: 85788 | K26: 290 | L26: #TeslaCoInnovation | M26: SustainabilityDrive | N26: 0.06371362
A27: P067 | B27: Facebook | C27: 45745 | D27: Carousel | E27: Check out our latest carousel on facebook! | F27: 4712 | G27: 568 | H27: 127 | I27: 84816 | J27: 84691 | K27: 100 | L27: #EVRevolution | M27: FSDUpdate | N27: 0.063749764
A28: P020 | B28: Instagram | C28: 45544 | D28: Carousel | E28: Check out our latest carousel on instagram! | F28: 4054 | G28: 488 | H28: 373 | I28: 77026 | J28: 76881 | K28: 25 | L28: #TeslaCoInnovation | M28: CybertruckLaunch | N28: 0.063809623
A29: P267 | B29: Twitter | C29: 45569 | D29: Reel | E29: Check out our latest reel on twitter! | F29: 4187 | G29: 66 | H29: 31 | I29: 66992 | J29: 66614 | K29: 62 | L29: #FutureOfDriving | N29: 0.063947934
A30: P073 | B30: Facebook | C30: 45583 | D30: Story | E30: Check out our latest story on facebook! | F30: 4126 | G30: 426 | H30: 486 | I30: 78394 | J30: 77798 | K30: 88 | L30: #FutureOfDriving | M30: SustainabilityDrive | N30: 0.064265122
A31: P135 | B31: Facebook | C31: 45624 | D31: Text | E31: Check out our latest text on facebook! | F31: 4213 | G31: 253 | H31: 434 | I31: 75834 | J31: 75437 | K31: 272 | L31: #FutureOfDriving | M31: SustainabilityDrive | N31: 0.064614817
A32: P197 | B32: Twitter | C32: 45587 | D32: Reel | E32: Check out our latest reel on twitter! | F32: 4782 | G32: 721 | H32: 82 | I32: 86076 | J32: 85339 | K32: 19 | L32: #EVRevolution | M32: CybertruckLaunch | N32: 0.064884521
A33: P144 | B33: YouTube | C33: 45593 | D33: Story | E33: Check out our latest story on youtube! | F33: 4929 | G33: 749 | H33: 452 | I33: 93651 | J33: 92810 | K33: 66 | L33: #EVRevolution | M33: SustainabilityDrive | N33: 0.065455788
A34: P086 | B34: YouTube | C34: 45684 | D34: Text | E34: Check out our latest text on youtube! | F34: 3428 | G34: 305 | H34: 85 | I34: 58276 | J34: 58052 | K34: 242 | L34: #EVRevolution | M34: SustainabilityDrive | N34: 0.065515821
A35: P086 | B35: YouTube | C35: 45684 | D35: Text | E35: Check out our latest text on youtube! | F35: 3428 | G35: 305 | H35: 85 | I35: 58276 | J35: 58052 | K35: 242 | L35: #BetterWithTesla | M35: SustainabilityDrive | N35: 0.065515821
A36: P005 | B36: YouTube | C36: 45469 | D36: Reel | E36: Check out our latest reel on youtube! | F36: 3557 | G36: 687 | H36: 424 | I36: 71140 | J36: 70701 | K36: 224 | L36: #EVRevolution | M36: CybertruckLaunch | N36: 0.065617093
A37: P005 | B37: YouTube | C37: 45469 | D37: Reel | E37: Check out our latest reel on youtube! | F37: 3557 | G37: 687 | H37: 424 | I37: 71140 | J37: 70701 | K37: 224 | L37: #TeslaCoInnovation | M37: CybertruckLaunch | N37: 0.065617093
A38: P270 | B38: YouTube | C38: 45672 | D38: Reel | E38: Check out our latest reel on youtube! | F38: 3774 | G38: 239 | H38: 39 | I38: 60384 | J38: 59490 | K38: 241 | L38: #TeslaCoInnovation | M38: FSDUpdate | N38: 0.067103869
A39: P237 | B39: Instagram | C39: 45587 | D39: Story | E39: Check out our latest story on instagram! | F39: 3770 | G39: 917 | H39: 129 | I39: 71630 | J39: 71322 | K39: 76 | L39: #FutureOfDriving | M39: CybertruckLaunch | N39: 0.067234399
A40: P288 | B40: YouTube | C40: 45764 | D40: Carousel | E40: Check out our latest carousel on youtube! | F40: 4780 | G40: 691 | H40: 380 | I40: 86040 | J40: 85743 | K40: 262 | L40: #FutureOfDriving | M40: FSDUpdate | N40: 0.068003254
...

Sheet TASK 2(1.1)
A1: Post ID | B1: Platform | C1: Date | D1: Content Type | E1: Post Text | F1: Likes | G1: Shares | H1: Comments | I1: Impressions | J1: Reach | K1: Clicks | L1: Hashtags | M1: Campaign_Name | N1: Engagement Rate
A2: P001 | B2: Twitter | C2: 45649 | D2: Reel | E2: Check out our latest reel on twitter! | F2: 1461 | G2: 184 | H2: 344 | I2: 21915 | J2: 21675 | K2: 15 | L2: #FutureOfDriving | M2: CybertruckLaunch | N2: =(F2+G2+H2)/I2 -> 0.090759754
A3: P001 | B3: Twitter | C3: 45649 | D3: Reel | E3: Check out our latest reel on twitter! | F3: 1461 | G3: 184 | H3: 344 | I3: 21915 | J3: 21675 | K3: 15 | L3: #AnytimeIsTeslaTime | M3: CybertruckLaunch | N3: =(F3+G3+H3)/I3 -> 0.090759754
A4: P002 | B4: Twitter | C4: 45750 | D4: Text | E4: Check out our latest text on twitter! | F4: 4054 | G4: 389 | H4: 493 | I4: 64864 | J4: 64383 | K4: 117 | L4: #TeslaCoInnovation | M4: ModelYCampaign | N4: =(F4+G4+H4)/I4 -> 0.076097681
A5: P002 | B5: Twitter | C5: 45750 | D5: Text | E5: Check out our latest text on twitter! | F5: 4054 | G5: 389 | H5: 493 | I5: 64864 | J5: 64383 | K5: 117 | L5: #BetterWithTesla | M5: ModelYCampaign | N5: =(F5+G5+H5)/I5 -> 0.076097681
A6: P003 | B6: YouTube | C6: 45789 | D6: Reel | E6: Check out our latest reel on youtube! | F6: 2795 | G6: 105 | H6: 49 | I6: 53105 | J6: 52307 | K6: 204 | L6: #TeslaCoInnovation | M6: FSDUpdate | N6: =(F6+G6+H6)/I6 -> 0.055531494
A7: P004 | B7: Instagram | C7: 45516 | D7: Story | E7: Check out our latest story on instagram! | F7: 2404 | G7: 363 | H7: 138 | I7: 19232 | J7: 18636 | K7: 128 | L7: #EVRevolution | M7: SustainabilityDrive | N7: =(F7+G7+H7)/I7 -> 0.15105033
A8: P005 | B8: YouTube | C8: 45469 | D8: Reel | E8: Check out our latest reel on youtube! | F8: 3557 | G8: 687 | H8: 424 | I8: 71140 | J8: 70701 | K8: 224 | L8: #EVRevolution | M8: CybertruckLaunch | N8: =(F8+G8+H8)/I8 -> 0.065617093
A9: P005 | B9: YouTube | C9: 45469 | D9: Reel | E9: Check out our latest reel on youtube! | F9: 3557 | G9: 687 | H9: 424 | I9: 71140 | J9: 70701 | K9: 224 | L9: #TeslaCoInnovation | M9: CybertruckLaunch | N9: =(F9+G9+H9)/I9 -> 0.065617093
A10: P006 | B10: Facebook | C10: 45596 | D10: Carousel | E10: Check out our latest carousel on facebook! | F10: 2945 | G10: 930 | H10: 355 | I10: 23560 | J10: 23275 | K10: 256 | L10: #TeslaCoInnovation | M10: ModelYCampaign | N10: =(F10+G10+H10)/I10 -> 0.1795416
A11: P007 | B11: Twitter | C11: 45467 | D11: Carousel | E11: Check out our latest carousel on twitter! | F11: 3860 | G11: 201 | H11: 279 | I11: 61760 | J11: 61660 | K11: 235 | L11: #TeslaCoInnovation | M11: ModelYCampaign | N11: =(F11+G11+H11)/I11 -> 0.070272021
A12: P008 | B12: YouTube | C12: 45486 | D12: Image | E12: Check out our latest image on youtube! | F12: 3929 | G12: 262 | H12: 278 | I12: 43219 | J12: 42841 | K12: 39 | L12: #EVRevolution | M12: SustainabilityDrive | N12: =(F12+G12+H12)/I12 -> 0.1034036
A13: P009 | B13: Facebook | C13: 45534 | D13: Text | E13: Check out our latest text on facebook! | F13: 3784 | G13: 808 | H13: 404 | I13: 56760 | J13: 56343 | K13: 131 | L13: #TeslaCoInnovation | M13: ModelYCampaign | N13: =(F13+G13+H13)/I13 -> 0.088019732
... A17: P013 | B17: YouTube | C17: 45614 | D17: Carousel | E17: Check out our latest carousel on youtube! | F17: 1171 | G17: 286 | H17: 231 | I17: 22249 | J17: 21282 | K17: 114 | L17: #EVRevolution | M17: CybertruckLaunch | N17: =(F17+G17+H17)/I17 -> 0.075868578
A18: P014 | B18: Facebook | C18: 45704 | D18: Story | E18: Check out our latest story on facebook! | F18: 4242 | G18: 555 | H18: 131 | I18: 33936 | J18: 33802 | K18: 265 | L18: #FutureOfDriving | N18: =(F18+G18+H18)/I18 -> 0.14521452
A19: P015 | B19: Facebook | C19: 45589 | D19: Video | E19: Check out our latest video on facebook! | F19: 3888 | G19: 604 | H19: 128 | I19: 77760 | J19: 77167 | K19: 20 | L19: #FutureOfDriving | M19: CybertruckLaunch | N19: =(F19+G19+H19)/I19 -> 0.05941358
A20: P016 | B20: Facebook | C20: 45530 | D20: Text | E20: Check out our latest text on facebook! | F20: 3452 | G20: 377 | H20: 360 | I20: 55232 | J20: 55075 | K20: 87 | L20: #FutureOfDriving | M20: FSDUpdate | N20: =(F20+G20+H20)/I20 -> 0.075843714
A21: P017 | B21: Facebook | C21: 45782 | D21: Text | E21: Check out our latest text on facebook! | F21: 4441 | G21: 511 | H21: 70 | I21: 53292 | J21: 53082 | K21: 159 | L21: #EVRevolution | M21: SustainabilityDrive | N21: =(F21+G21+H21)/I21 -> 0.094235533
A22: P018 | B22: Instagram | C22: 45523 | D22: Reel | E22: Check out our latest reel on instagram! | F22: 3000 | G22: 382 | H22: 325 | I22: 36000 | J22: 35819 | K22: 19 | L22: #FutureOfDriving | M22: CybertruckLaunch | N22: =(F22+G22+H22)/I22 -> 0.10297222
A23: P019 | B23: Instagram | C23: 45466 | D23: Video | E23: Check out our latest video on instagram! | F23: 1071 | G23: 519 | H23: 22 | I23: 16065 | J23: 15865 | K23: 103 | L23: #TeslaCoInnovation | M23: SustainabilityDrive | N23: =(F23+G23+H23)/I23 -> 0.10034236
A24: P020 | B24: Instagram | C24: 45544 | D24: Carousel | E24: Check out our latest carousel on instagram! | F24: 4054 | G24: 488 | H24: 373 | I24: 77026 | J24: 76881 | K24: 25 | L24: #TeslaCoInnovation | M24: CybertruckLaunch | N24: =(F24+G24+H24)/I24 -> 0.063809623
A25: P021 | B25: Instagram | C25: 45661 | D25: Reel | E25: Check out our latest reel on instagram! | F25: 4838 | G25: 640 | H25: 128 | I25: 72570 | J25: 72396 | K25: 83 | L25: #FutureOfDriving | M25: SustainabilityDrive | N25: =(F25+G25+H25)/I25 -> 0.077249552
A26: P022 | B26: Facebook | C26: 45715 | D26: Text | E26: Check out our latest text on facebook! | F26: 1570 | G26: 187 | H26: 260 | I26: 25120 | J26: 24613 | K26: 133 | L26: #TeslaCoInnovation | M26: SustainabilityDrive | N26: =(F26+G26+H26)/I26 -> 0.080294586
A27: P023 | B27: Facebook | C27: 45602 | D27: Video | E27: Check out our latest video on facebook! | F27: 1606 | G27: 547 | H27: 316 | I27: 32120 | J27: 31736 | K27: 225 | L27: #TeslaCoInnovation | M27: ModelYCampaign | N27: =(F27+G27+H27)/I27 -> 0.076867995
A28: P023 | B28: Facebook | C28: 45602 | D28: Video | E28: Check out our latest video on facebook! | F28: 1606 | G28: 547 | H28: 316 | I28: 32120 | J28: 31736 | K28: 225 | L28: #AnytimeIsTeslaTime | M28: ModelYCampaign | N28: =(F28+G28+H28)/I28 -> 0.076867995
A29: P024 | B29: Facebook | C29: 45680 | D29: Video | E29: Check out our latest video on facebook! | F29: 3961 | G29: 761 | H29: 131 | I29: 67337 | J29: 66615 | K29: 161 | L29: #FutureOfDriving | M29: FSDUpdate | N29: =(F29+G29+H29)/I29 -> 0.072070333
A30: P025 | B30: Twitter | C30: 45757 | D30: Carousel | E30: Check out our latest carousel on twitter! | F30: 3128 | G30: 211 | H30: 197 | I30: 59432 | J30: 59182 | K30: 238 | L30: #EVRevolution | N30: =(F30+G30+H30)/I30 -> 0.059496568
A31: P026 | B31: YouTube | C31: 45752 | D31: Reel | E31: Check out our latest reel on youtube! | F31: 3009 | G31: 413 | H31: 358 | I31: 42126 | J31: 41309 | K31: 211 | L31: #FutureOfDriving | M31: ModelYCampaign | N31: =(F31+G31+H31)/I31 -> 0.089730808
A32: P027 | B32: YouTube | C32: 45552 | D32: Text | E32: Check out our latest text on youtube! | F32: 2076 | G32: 195 | H32: 104 | I32: 33216 | J32: 32244 | K32: 51 | L32: #FutureOfDriving | M32: SustainabilityDrive | N32: =(F32+G32+H32)/I32 -> 0.071501686
A33: P028 | B33: Instagram | C33: 45720 | D33: Video | E33: Check out our latest video on instagram! | F33: 432 | G33: 624 | H33: 123 | I33: 6912 | J33: 6259 | K33: 79 | L33: #FutureOfDriving | M33: SustainabilityDrive | N33: =(F33+G33+H33)/I33 -> 0.17057292
A34: P029 | B34: Instagram | C34: 45688 | D34: Carousel | E34: Check out our latest carousel on instagram! | F34: 2566 | G34: 118 | H34: 37 | I34: 12830 | J34: 12264 | K34: 221 | L34: #FutureOfDriving | M34: FSDUpdate | N34: =(F34+G34+H34)/I34 -> 0.21208106
A35: P030 | B35: Instagram | C35: 45713 | D35: Video | E35: Check out our latest video on instagram! | F35: 3095 | G35: 39 | H35: 78 | I35: 55710 | J35: 54808 | K35: 93 | L35: #EVRevolution | N35: =(F35+G35+H35)/I35 -> 0.057655717
A36: P031 | B36: Instagram | C36: 45642 | D36: Text | E36: Check out our latest text on instagram! | F36: 438 | G36: 153 | H36: 275 | I36: 3066 | J36: 2701 | K36: 282 | L36: #TeslaCoInnovation | M36: ModelYCampaign | N36: =(F36+G36+H36)/I36 -> 0.28245271
A37: P032 | B37: Twitter | C37: 45504 | D37: Carousel | E37: Check out our latest carousel on twitter! | F37: 2278 | G37: 10 | H37: 321 | I37: 13668 | J37: 12676 | K37: 275 | L37: #EVRevolution | M37: CybertruckLaunch | N37: =(F37+G37+H37)/I37 -> 0.19088382
A38: P033 | B38: Facebook | C38: 45525 | D38: Image | E38: Check out our latest image on facebook! | F38: 1407 | G38: 400 | H38: 351 | I38: 16884 | J38: 15954 | K38: 113 | L38: #TeslaCoInnovation | M38: CybertruckLaunch | N38: =(F38+G38+H38)/I38 -> 0.12781331
A39: P034 | B39: Facebook | C39: 45742 | D39: Text | E39: Check out our latest text on facebook! | F39: 1652 | G39: 89 | H39: 357 | I39: 29736 | J39: 28771 | K39: 215 | L39: #TeslaCoInnovation | M39: FSDUpdate | N39: =(F39+G39+H39)/I39 -> 0.07055421
A40: P035 | B40: Instagram | C40: 45626 | D40: Video | E40: Check out our latest video on instagram! | F40: 3775 | G40: 16 | H40: 239 | I40: 33975 | J40: 33310 | K40: 271 | L40: #FutureOfDriving | M40: ModelYCampaign | N40: =(F40+G40+H40)/I40 -> 0.11861663
A41: P036 | B41: Instagram | C41: 45766 | D41: Story | E41: Check out our latest story on instagram! | F41: 4518 | G41: 285 | H41: 383 | I41: 67770 | J41: 67621 | K41: 31 | L41: #EVRevolution | M41: ModelYCampaign | N41: =(F41+G41+H41)/I41 -> 0.076523535
A42: P037 | B42: Facebook | C42: 45663 | D42: Carousel | E42: Check out our latest carousel on facebook! | F42: 3024 | G42: 925 | H42: 350 | I42: 24192 | J42: 23518 | K42: 36 | L42: #EVRevolution | M42: ModelYCampaign | N42: =(F42+G42+H42)/I42 -> 0.17770337
A43: P038 | B43: YouTube | C43: 45705 | D43: Reel | E43: Check out our latest reel on youtube! | F43: 3138 | G43: 123 | H43: 291 | I43: 28242 | J43: 27550 | K43: 87 | L43: #TeslaCoInnovation | M43: SustainabilityDrive | N43: =(F43+G43+H43)/I43 -> 0.12577013
...

Sheet TASK 2(4)
A1: Row Labels | B1: Average of Clicks
A2: #AnytimeIsTeslaTime | B2: 161.2
A3: #TeslaCoInnovation | B3: 158.65421
A4: #EVRevolution | B4: 151.52941
A5: #FutureOfDriving | B5: 144.03883
A6: #BetterWithTesla | B6: 114.85714
A7: #SmoothLikeNitroTesla | B7: 111.8
A8: Grand Total | B8: 150.58702

Sheet TASK 3(1)
A1: Week_Start_Date | B1: Platform | C1: New_Followers | D1: Unfollows | E1: Total_Followers | F1: Engagement_Rate | G1: Ad_Spend | H1: Net_Growth
A2: 2024-06-03 | B2: Instagram | C2: 1135 | D2: 88 | E2: 344084 | F2: 8.06 | G2: 5904 | H2: =C2-D2 -> 1047
A3: 2024-06-03 | B3: Facebook | C3: 1312 | D3: 310 | E3: 42654 | F3: 4.98 | G3: 9566 | H3: =C3-D3 -> 1002
A4: 2024-06-03 | B4: Twitter | C4: 584 | D4: 169 | E4: 146834 | F4: 8.31 | G4: 26752 | H4: =C4-D4 -> 415
A5: 2024-06-03 | B5: YouTube | C5: 1535 | D5: 445 | E5: 395536 | F5: 4.11 | G5: 30671 | H5: =C5-D5 -> 1090
A6: 2024-06-10 | B6: Instagram | C6: 656 | D6: 139 | E6: 49157 | F6: 9.05 | G6: 9920 | H6: =C6-D6 -> 517
A7: 2024-06-10 | B7: Facebook | C7: 1697 | D7: 414 | E7: 316555 | F7: 2.37 | G7: 7924 | H7: =C7-D7 -> 1283
A8: 2024-06-10 | B8: Twitter | C8: 436 | D8: 250 | E8: 254347 | F8: 4.01 | G8: 8912 | H8: =C8-D8 -> 186
A9: 2024-06-10 | B9: YouTube | C9: 1197 | D9: 203 | E9: 413878 | F9: 3.16 | G9: 21205 | H9: =C9-D9 -> 994
A10: 2024-06-17 | B10: Instagram | C10: 1048 | D10: 155 | E10: 456946 | F10: 2.46 | G10: 11329 | H10: =C10-D10 -> 893
A11: 2024-06-17 | B11: Facebook | C11: 1753 | D11: 371 | E11: 169496 | F11: 8.11 | G11: 46670 | H11: =C11-D11 -> 1382
A12: 2024-06-17 | B12: Twitter | C12: 1335 | D12: 40 | E12: 122732 | F12: 8.19 | G12: 22482 | H12: =C12-D12 -> 1295
A13: 2024-06-17 | B13: YouTube | C13: 403 | D13: 66 | E13: 382851 | F13: 3.49 | G13: 24313 | H13: =C13-D13 -> 337
... A201: 2025-05-12 | B201: YouTube | C201: 119 | D201: 456 | E201: 82558 | F201: 6.81 | G201: 12174 | H201: =C201-D201 -> -337

Sheet TASK 3(2)
A3: Row Labels | B3: Average of Engagement_Rate
A4: Instagram | B4: 5.7156
A5: Twitter | B5: 5.6558
A6: Facebook | B6: 5.6486
A7: YouTube | B7: 5.5588
A8: Grand Total | B8: 5.6447

Sheet TASK 3(3)
A1: Row Labels | B1: Sum of Net_Growth | C1: Average of Engagement_Rate | D1: Sum of Ad_Spend
A2: Facebook | B2: 35557 | C2: 5.6486 | D2: 1379539
A3: Instagram | B3: 48004 | C3: 5.7156 | D3: 1164373
A4: Twitter | B4: 41177 | C4: 5.6558 | D4: 1060357
A5: YouTube | B5: 35367 | C5: 5.5588 | D5: 1228647
A6: Grand Total | B6: 160105 | C6: 5.6447 | D6: 4832916

Sheet TASK 4(1)
A1: Post ID | B1: Platform | C1: Date | D1: Content Type | E1: Post Text | F1: Likes | G1: Shares | H1: Comments | I1: Impressions | J1: Reach | K1: Clicks | L1: Hashtags | M1: Campaign_Name | N1: Avg_Engagement
A2: P001 | B2: Twitter | C2: 45649 | D2: Reel | E2: Check out our latest reel on twitter! | F2: 1461 | G2: 184 | H2: 344 | I2: 21915 | J2: 21675 | K2: 15 | L2: #FutureOfDriving | M2: CybertruckLaunch | N2: 5.6558
A3: P001 | B3: Twitter | C3: 45649 | D3: Reel | E3: Check out our latest reel on twitter! | F3: 1461 | G3: 184 | H3: 344 | I3: 21915 | J3: 21675 | K3: 15 | L3: #AnytimeIsTeslaTime | M3: CybertruckLaunch | N3: 5.6558
A4: P002 | B4: Twitter | C4: 45750 | D4: Text | E4: Check out our latest text on twitter! | F4: 4054 | G4: 389 | H4: 493 | I4: 64864 | J4: 64383 | K4: 117 | L4: #TeslaCoInnovation | M4: ModelYCampaign | N4: 5.7156
A5: P002 | B5: Twitter | C5: 45750 | D5: Text | E5: Check out our latest text on twitter! | F5: 4054 | G5: 389 | H5: 493 | I5: 64864 | J5: 64383 | K5: 117 | L5: #BetterWithTesla | M5: ModelYCampaign | N5: 5.5588
A6: P003 | B6: YouTube | C6: 45789 | D6: Reel | E6: Check out our latest reel on youtube! | F6: 2795 | G6: 105 | H6: 49 | I6: 53105 | J6: 52307 | K6: 204 | L6: #TeslaCoInnovation | M6: FSDUpdate | N6: 5.5588
A7: P004 | B7: Instagram | C7: 45516 | D7: Story | E7: Check out our latest story on instagram! | F7: 2404 | G7: 363 | H7: 138 | I7: 19232 | J7: 18636 | K7: 128 | L7: #EVRevolution | M7: SustainabilityDrive | N7: 5.6486
A8: P005 | B8: YouTube | C8: 45469 | D8: Reel | E8: Check out our latest reel on youtube! | F8: 3557 | G8: 687 | H8: 424 | I8: 71140 | J8: 70701 | K8: 224 | L8: #EVRevolution | M8: CybertruckLaunch | N8: 5.6558
A9: P005 | B9: YouTube | C9: 45469 | D9: Reel | E9: Check out our latest reel on youtube! | F9: 3557 | G9: 687 | H9: 424 | I9: 71140 | J9: 70701 | K9: 224 | L9: #TeslaCoInnovation | M9: CybertruckLaunch | N9: 5.5588
A10: P006 | B10: Facebook | C10: 45596 | D10: Carousel | E10: Check out our latest carousel on facebook! | F10: 2945 | G10: 930 | H10: 355 | I10: 23560 | J10: 23275 | K10: 256 | L10: #TeslaCoInnovation | M10: ModelYCampaign | N10: 5.6486
A11: P007 | B11: Twitter | C11: 45467 | D11: Carousel | E11: Check out our latest carousel on twitter! | F11: 3860 | G11: 201 | H11: 279 | I11: 61760 | J11: 61660 | K11: 235 | L11: #TeslaCoInnovation | M11: ModelYCampaign | N11: 5.6486
A12: P008 | B12: YouTube | C12: 45486 | D12: Image | E12: Check out our latest image on youtube! | F12: 3929 | G12: 262 | H12: 278 | I12: 43219 | J12: 42841 | K12: 39 | L12: #EVRevolution | M12: SustainabilityDrive | N12: 5.7156
A13: P009 | B13: Facebook | C13: 45534 | D13: Text | E13: Check out our latest text on facebook! | F13: 3784 | G13: 808 | H13: 404 | I13: 56760 | J13: 56343 | K13: 131 | L13: #TeslaCoInnovation | M13: ModelYCampaign | N13: 5.6486
... A17: P013 | B17: YouTube | C17: 45614 | D17: Carousel | E17: Check out our latest carousel on youtube! | F17: 1171 | G17: 286 | H17: 231 | I17: 22249 | J17: 21282 | K17: 114 | L17: #EVRevolution | M17: CybertruckLaunch | N17: 5.6486
A18: P014 | B18: Facebook | C18: 45704 | D18: Story | E18: Check out our latest story on facebook! | F18: 4242 | G18: 555 | H18: 131 | I18: 33936 | J18: 33802 | K18: 265 | L18: #FutureOfDriving | N18: 5.6486
A19: P015 | B19: Facebook | C19: 45589 | D19: Video | E19: Check out our latest video on facebook! | F19: 3888 | G19: 604 | H19: 128 | I19: 77760 | J19: 77167 | K19: 20 | L19: #FutureOfDriving | M19: CybertruckLaunch | N19: 5.7156
A20: P016 | B20: Facebook | C20: 45530 | D20: Text | E20: Check out our latest text on facebook! | F20: 3452 | G20: 377 | H20: 360 | I20: 55232 | J20: 55075 | K20: 87 | L20: #FutureOfDriving | M20: FSDUpdate | N20: 5.7156
A21: P017 | B21: Facebook | C21: 45782 | D21: Text | E21: Check out our latest text on facebook! | F21: 4441 | G21: 511 | H21: 70 | I21: 53292 | J21: 53082 | K21: 159 | L21: #EVRevolution | M21: SustainabilityDrive | N21: 5.7156
A22: P018 | B22: Instagram | C22: 45523 | D22: Reel | E22: Check out our latest reel on instagram! | F22: 3000 | G22: 382 | H22: 325 | I22: 36000 | J22: 35819 | K22: 19 | L22: #FutureOfDriving | M22: CybertruckLaunch | N22: 5.7156
A23: P019 | B23: Instagram | C23: 45466 | D23: Video | E23: Check out our latest video on instagram! | F23: 1071 | G23: 519 | H23: 22 | I23: 16065 | J23: 15865 | K23: 103 | L23: #TeslaCoInnovation | M23: SustainabilityDrive | N23: 5.6486
A24: P020 | B24: Instagram | C24: 45544 | D24: Carousel | E24: Check out our latest carousel on instagram! | F24: 4054 | G24: 488 | H24: 373 | I24: 77026 | J24: 76881 | K24: 25 | L24: #TeslaCoInnovation | M24: CybertruckLaunch | N24: 5.6486
A25: P021 | B25: Instagram | C25: 45661 | D25: Reel | E25: Check out our latest reel on instagram! | F25: 4838 | G25: 640 | H25: 128 | I25: 72570 | J25: 72396 | K25: 83 | L25: #FutureOfDriving | M25: SustainabilityDrive | N25: 5.6486
A26: P022 | B26: Facebook | C26: 45715 | D26: Text | E26: Check out our latest text on facebook! | F26: 1570 | G26: 187 | H26: 260 | I26: 25120 | J26: 24613 | K26: 133 | L26: #TeslaCoInnovation | M26: SustainabilityDrive | N26: 5.6558
A27: P023 | B27: Facebook | C27: 45602 | D27: Video | E27: Check out our latest video on facebook! | F27: 1606 | G27: 547 | H27: 316 | I27: 32120 | J27: 31736 | K27: 225 | L27: #TeslaCoInnovation | M27: ModelYCampaign | N27: 5.5588
A28: P023 | B28: Facebook | C28: 45602 | D28: Video | E28: Check out our latest video on facebook! | F28: 1606 | G28: 547 | H28: 316 | I28: 32120 | J28: 31736 | K28: 225 | L28: #AnytimeIsTeslaTime | M28: ModelYCampaign | N28: 5.5588
A29: P024 | B29: Facebook | C29: 45680 | D29: Video | E29: Check out our latest video on facebook! | F29: 3961 | G29: 761 | H29: 131 | I29: 67337 | J29: 66615 | K29: 161 | L29: #FutureOfDriving | M29: FSDUpdate | N29: 5.7156
A30: P025 | B30: Twitter | C30: 45757 | D30: Carousel | E30: Check out our latest carousel on twitter! | F30: 3128 | G30: 211 | H30: 197 | I30: 59432 | J30: 59182 | K30: 238 | L30: #EVRevolution | N30: 5.7156
A31: P026 | B31: YouTube | C31: 45752 | D31: Reel | E31: Check out our latest reel on youtube! | F31: 3009 | G31: 413 | H31: 358 | I31: 42126 | J31: 41309 | K31: 211 | L31: #FutureOfDriving | M31: ModelYCampaign | N31: 5.7156
A32: P027 | B32: YouTube | C32: 45552 | D32: Text | E32: Check out our latest text on youtube! | F32: 2076 | G32: 195 | H32: 104 | I32: 33216 | J32: 32244 | K32: 51 | L32: #FutureOfDriving | M32: SustainabilityDrive | N32: 5.7156
A33: P028 | B33: Instagram | C33: 45720 | D33: Video | E33: Check out our latest video on instagram! | F33: 432 | G33: 624 | H33: 123 | I33: 6912 | J33: 6259 | K33: 79 | L33: #FutureOfDriving | M33: SustainabilityDrive | N33: 5.6558
